Workbook

Sheet Database Konstelation
A1: - | C1: APLIKASI PHP CRUD
A3: No | B3: NAMA | C3: JUDUL APK | D3: OBJEK1 | E3: OBJEK2 | F3: OBJEK3 | G3: OBJEK4 | H3: SUBJECT 1 | I3: SUBJECT 2 | J3: SUBJECT 3 | K3: TRANSAKSI 1 | L3: TRANSAKSI 2
A4: 1 | B4: Ahmadi Muslim | C4: Web RPL | D4: Konten | E4: Komentar | F4: - | G4: - | H4: User | I4: Pengunjung | K4: - | L4: -
A5: 1 | B5: Ahmadi Muslim | C5: Koperasi | D5: barang | E5: inventaris | F5: suplier | G5: merk | H5: user | I5: pembeli | K5: penjualan | L5: detilpenjualan | M5: =B5 -> Ahmadi Muslim
A6: 2 | B6: Abyadh Hidayatullah | C6: Inventori sekolah | D6: barang | E6: katagori | F6: penyuplai | G6: merek | H6: user | I6: - | K6: barangmasuk | M6: =B6 -> Abyadh Hidayatullah
A7: 3 | B7: Adinda Aprilia | C7: SPMB | D7: data | F7: - | G7: - | H7: user | K7: pendaftaran | M7: =B7 -> Adinda Aprilia
A8: 4 | B8: Aida Lidiya Nabilah | C8: Inventaris Kelas | D8: Barang | E8: Kelas | F8: Kategori | G8: Kondisi | H8: user | I8: Petugas | J8: - | K8: Peminjaman | L8: detailpeminjaman | M8: =B8 -> Aida Lidiya Nabilah
A9: 5 | B9: Alya 'Aqila Zulfaa | C9: Surat izin siswa | D9: suratizin | E9: kelas | F9: - | G9: - | H9: user | I9: siswa | K9: Pengajuan | L9: Persetujuan | M9: =B9 -> Alya 'Aqila Zulfaa
A10: 6 | B10: Amelia Fathar Nst | C10: Jadwal Pelajaran | D10: mapel | E10: kelas | F10: ruangan | G10: - | H10: user | I10: guru | K10: penjadwalan | L10: detiljadwal | M10: =B10 -> Amelia Fathar Nst
A11: 7 | B11: Cahaya Putri Asyasyuara E. | C11: Perpustakaan | D11: buku | E11: kategori | F11: - | H11: user | I11: siswa | K11: peminjaman | L11: detailpeminjaman | M11: =B11 -> Cahaya Putri Asyasyuara E.
A12: 8 | B12: Dewi Rahmah | C12: web sekolah | D12: konten | E12: komentar | F12: - | G12: - | H12: user | I12: pengunjung | K12: - | L12: - | M12: =B12 -> Dewi Rahmah
A13: 9 | B13: Eka Lisa Apriliani | C13: Lapor Buli | D13: buli | E13: kategori | F13: sanksi | G13: - | H13: user | I13: siswa | K13: pengajuan | M13: =B13 -> Eka Lisa Apriliani
A14: 1 | B14: Faldan Affadil | C14: piket guru | D14: jadwalpiket | E14: - | F14: jam | G14: - | H14: user | I14: guru | K14: - | M14: =B14 -> Faldan Affadil
A15: 11 | B15: Gella Meylita | C15: Absen OSIS | D15: absen | F15: - | G15: - | H15: user | I15: anggota | K15: kegiatan | M15: =B15 -> Gella Meylita
A16: 12 | B16: Haikhal Syahputra | H16: user | M16: =B16 -> Haikhal Syahputra
A17: 13 | B17: Hayfa Sakhiy | C17: web Ekskul | D17: konten | E17: komentar | F17: - | G17: - | H17: user | I17: pengunjung | K17: - | M17: =B17 -> Hayfa Sakhiy
A18: 14 | B18: Mariescha Najwaa | C18: lapor kebersihan | E18: kategori | F18: lokasi | G18: - | H18: user | I18: siswa | K18: laporan | L18: penanganan | M18: =B18 -> Mariescha Najwaa
A19: 15 | B19: Maya | C19: Keterlambatan siswa | D19: - | E19: jadwal | F19: - | G19: - | H19: user | I19: siswa | K19: keterlambatan | L19: - | M19: =B19 -> Maya
A20: 16 | B20: Miftahul Zannah | C20: buku tamu | D20: - | E20: kategori | F20: - | G20: - | H20: user | I20: pengunjung | K20: pengisianbuku | M20: =B20 -> Miftahul Zannah
A21: 17 | B21: Nazwa Ramadhani | C21: catat pelanggaran | E21: sanksi | F21: - | H21: user | I21: siswa | J21: walimurid | K21: pelanggaran | M21: =B21 -> Nazwa Ramadhani
A22: 18 | B22: Nazzira Pusvita Sari | C22: tata usaha | D22: - | E22: kategori | F22: - | G22: - | H22: user | I22: pengunjung | J22: - | K22: pengisianbuku | L22: - | M22: =B22 -> Nazzira Pusvita Sari
A23: 19 | B23: Novi Yanti | C23: absen kehadiran siswa | D23: jadwal | F23: - | G23: - | H23: user | I23: siswa | J23: walimurid | K23: kehadiran | M23: =B23 -> Novi Yanti
A24: 20 | B24: Nurhalizah | C24: jadwal pelajaran | D24: jadwal | F24: - | H24: user | I24: guru | M24: =B24 -> Nurhalizah
A25: 21 | B25: Nurul Aini Nasution | C25: pemilihan osis | D25: kandidat | E25: - | F25: - | G25: - | H25: user | I25: pemilih | J25: - | K25: pemilihan | M25: =B25 -> Nurul Aini Nasution
A26: 22 | B26: Raffa Ramadhan | C26: aplikasi pengumpulan tugas siswa | D26: tugas | F26: mapel | G26: kelas | H26: user | I26: guru | J26: siswa | K26: penilaian | M26: =B26 -> Raffa Ramadhan
A27: 23 | B27: Reisha Armaini | C27: LMS | D27: tugas | E27: kategori | F27: deadline | G27: status | H27: user | I27: guru | J27: siswa | K27: penugasan | M27: =B27 -> Reisha Armaini
A28: 24 | B28: Sarki Sepriana | C28: asuransi kesehatan untuk guru | D28: cekup | E28: dokumen | H28: user | I28: guru | K28: klaimasuransi | M28: =B28 -> Sarki Sepriana
A29: 25 | B29: Sevenna Mesyera | C29: buku anggota Osis | D29: Lokasi | E29: kategori | F29: - | G29: - | H29: user | I29: panitia | K29: agenda | L29: - | M29: =B29 -> Sevenna Mesyera
A30: 26 | B30: Shifa Rahmadani | C30: Pengajuan Perlengkapan Alat LAB | D30: alat | E30: lab | F30: kategori | H30: user | I30: guru | K30: pengajuan | L30: detailtransaksi | M30: =B30 -> Shifa Rahmadani
A31: 27 | B31: Tasya Aulia Putri | C31: izin keluar kelas | D31: - | E31: - | F31: Izin | G31: - | H31: user | I31: guru | J31: siswa | K31: pengajuan | L31: - | M31: =B31 -> Tasya Aulia Putri
A32: 28 | B32: Teuku Abdul Razaq | C32: peminjaman alat sarana | D32: alat | E32: kategori | F32: merek | G32: lokasi | H32: user | K32: peminjaman | M32: =B32 -> Teuku Abdul Razaq
A33: 29 | B33: Wanda Afrilia | C33: pengaduan kerusakan fasilitas sklh | D33: fasilitas | E33: kategori | F33: ruangan | G33: - | H33: user | I33: siswa | J33: teknisi | K33: pengaduan | L33: - | M33: =B33 -> Wanda Afrilia
A34: 30 | B34: Widya Ulfa | C34: manejemen prestasi siswa | D34: prestasi | E34: kategori | F34: tingkat | G34: sartifikat | H34: user | I34: siswa | J34: gurupembina | K34: pendaftaran | L34: falidasiprestasi | M34: =B34 -> Widya Ulfa
A35: 31 | B35: Zahira Nursafa | C35: uang kas | D35: dana | E35: kategori | H35: user | I35: siswa | K35: pemasukan | L35: pengeluaran | M35: =B35 -> Zahira Nursafa
A36: 32 | B36: Zakwan Abdul Hady | C36: aplikasi kantin sekolah | D36: makanan | E36: minuman | H36: user | I36: pembeli | J36: suplayer | K36: penjualan | L36: detailpenjual | M36: =B36 -> Zakwan Abdul Hady
A37: 33 | B37: Zsaskia Meiranda | C37: pendaftaran ekskul | D37: ekskul | E37: - | F37: - | G37: - | H37: user | I37: siswa | K37: pendaftaran | L37: - | M37: =B37 -> Zsaskia Meiranda
A38: 34 | B38: Zulaika Fatarani | C38: uks | D38: barang | G38: -- | H38: user | I38: siswa | J38: guru | K38: penanganan | M38: =B38 -> Zulaika Fatarani
B40: Nama | C40: Subjek
B41: Adita Dwi Rezeki P | C41: DDL1
B42: Aditya Gufran | C42: TCL
...

Sheet Judul APK Crud 2026
A2: JUDUL APLIKASI LARAVEL XIRPL2 (GENAP)
A4: No | B4: NAMA | C4: TEMPAT/Divisi | D4: Narasumber | E4: Judul Aplikasi | F4: ERD | G4: ERT | H4: PHP | I4: TABEL DI DB | Q4: FITUR APLIKASI | AE4: GIT
A5: 1 | B5: ='Database Konstelation'!B5 -> Ahmadi Muslim | C5: Koperasi | D5: Bu Teteh | E5: ='Database Konstelation'!C5 -> Koperasi | I5: user | Q5: Template/LP | R5: Login | S5: Register | T5: Dashboard | U5: Laporan | V5: admin | W5: pembeli | X5: produk | Y5: kategori | Z5: suplier | AA5: transaksi | AB5: detiltransaksi | AC5: asal | AD5: =B5 -> Ahmadi Muslim
A6: 2 | B6: ='Database Konstelation'!B6 -> Abyadh Hidayatullah | E6: ='Database Konstelation'!C6 -> Inventori sekolah | I6: user | Q6: Template/LP | R6: Login | S6: Register | T6: Dashboard | U6: Laporan | V6: user | AD6: =B6 -> Abyadh Hidayatullah
A7: 3 | B7: ='Database Konstelation'!B7 -> Adinda Aprilia | D7: bu linda | E7: ='Database Konstelation'!C7 -> SPMB | I7: user | Q7: Template/LP | R7: Login | S7: Register | T7: Dashboard | U7: Laporan | V7: user | AD7: =B7 -> Adinda Aprilia
A8: 4 | B8: ='Database Konstelation'!B8 -> Aida Lidiya Nabilah | E8: ='Database Konstelation'!C8 -> Inventaris Kelas | I8: user | Q8: Template/LP | R8: Login | S8: Register | T8: Dashboard | U8: Laporan | V8: user | AD8: =B8 -> Aida Lidiya Nabilah
A9: 5 | B9: ='Database Konstelation'!B9 -> Alya 'Aqila Zulfaa | D9: bu sri | E9: ='Database Konstelation'!C9 -> Surat izin siswa | I9: user | Q9: Template/LP | R9: Login | S9: Register | T9: Dashboard | U9: Laporan | V9: user | AD9: =B9 -> Alya 'Aqila Zulfaa
A10: 6 | B10: ='Database Konstelation'!B10 -> Amelia Fathar Nst | D10: bu ersa | E10: ='Database Konstelation'!C10 -> Jadwal Pelajaran | I10: user | Q10: Template/LP | R10: Login | S10: Register | T10: Dashboard | U10: Laporan | V10: user | AD10: =B10 -> Amelia Fathar Nst
A11: 7 | B11: ='Database Konstelation'!B11 -> Cahaya Putri Asyasyuara E. | D11: buk ana | E11: ='Database Konstelation'!C11 -> Perpustakaan | I11: user | Q11: Template/LP | R11: Login | S11: Register | T11: Dashboard | U11: Laporan | V11: user | AD11: =B11 -> Cahaya Putri Asyasyuara E.
A12: 8 | B12: ='Database Konstelation'!B12 -> Dewi Rahmah | C12: sekolah | E12: ='Database Konstelation'!C12 -> web sekolah | I12: user | Q12: Template/LP | R12: Login | S12: Register | T12: Dashboard | U12: Laporan | V12: user | AD12: =B12 -> Dewi Rahmah
A13: 9 | B13: ='Database Konstelation'!B13 -> Eka Lisa Apriliani | C13: kesiswaan | D13: bu har | E13: ='Database Konstelation'!C13 -> Lapor Buli | I13: user | Q13: Template/LP | R13: Login | S13: Register | T13: Dashboard | U13: Laporan | V13: user | AD13: =B13 -> Eka Lisa Apriliani
A14: 10 | B14: ='Database Konstelation'!B14 -> Faldan Affadil | E14: ='Database Konstelation'!C14 -> piket guru | I14: user | Q14: Template/LP | R14: Login | S14: Register | T14: Dashboard | U14: Laporan | V14: user | AD14: =B14 -> Faldan Affadil
A15: 11 | B15: ='Database Konstelation'!B15 -> Gella Meylita | C15: ruang osis | D15: buk maya | E15: ='Database Konstelation'!C15 -> Absen OSIS | I15: user | Q15: Template/LP | R15: Login | S15: Register | T15: Dashboard | U15: Laporan | V15: user | AD15: =B15 -> Gella Meylita
A16: 12 | B16: ='Database Konstelation'!B16 -> Haikhal Syahputra | E16: ='Database Konstelation'!C16 -> 0 | I16: user | Q16: Template/LP | R16: Login | S16: Register | T16: Dashboard | U16: Laporan | V16: user | AD16: =B16 -> Haikhal Syahputra
A17: 13 | B17: ='Database Konstelation'!B17 -> Hayfa Sakhiy | C17: web ekskul | D17: bu maya | E17: ='Database Konstelation'!C17 -> web Ekskul | I17: user | Q17: Template/LP | R17: Login | S17: Register | T17: Dashboard | U17: Laporan | V17: user | AD17: =B17 -> Hayfa Sakhiy
A18: 14 | B18: ='Database Konstelation'!B18 -> Mariescha Najwaa | D18: pak mahdi | E18: ='Database Konstelation'!C18 -> lapor kebersihan | I18: user | Q18: Template/LP | R18: Login | S18: Register | T18: Dashboard | U18: Laporan | V18: user | AD18: =B18 -> Mariescha Najwaa
A19: 15 | B19: ='Database Konstelation'!B19 -> Maya | D19: bu icha | E19: ='Database Konstelation'!C19 -> Keterlambatan siswa | I19: user | Q19: Template/LP | R19: Login | S19: Register | T19: Dashboard | U19: Laporan | V19: user | AD19: =B19 -> Maya
A20: 16 | B20: ='Database Konstelation'!B20 -> Miftahul Zannah | C20: TU | D20: bu sri | E20: ='Database Konstelation'!C20 -> buku tamu | I20: user | Q20: Template/LP | R20: Login | S20: Register | T20: Dashboard | U20: Laporan | V20: user | AD20: =B20 -> Miftahul Zannah
A21: 17 | B21: ='Database Konstelation'!B21 -> Nazwa Ramadhani | C21: ruang osis | D21: buk icha | E21: ='Database Konstelation'!C21 -> catat pelanggaran | I21: user | Q21: Template/LP | R21: Login | S21: Register | T21: Dashboard | U21: Laporan | V21: user | AD21: =B21 -> Nazwa Ramadhani
A22: 18 | B22: ='Database Konstelation'!B22 -> Nazzira Pusvita Sari | E22: ='Database Konstelation'!C22 -> tata usaha | I22: user | Q22: Template/LP | R22: Login | S22: Register | T22: Dashboard | U22: Laporan | V22: user | AD22: =B22 -> Nazzira Pusvita Sari
A23: 19 | B23: ='Database Konstelation'!B23 -> Novi Yanti | C23: kantor guru | D23: mem mimi | E23: ='Database Konstelation'!C23 -> absen kehadiran siswa | I23: user | Q23: Template/LP | R23: Login | S23: Register | T23: Dashboard | U23: Laporan | V23: user | AD23: =B23 -> Novi Yanti
A24: 20 | B24: ='Database Konstelation'!B24 -> Nurhalizah | E24: ='Database Konstelation'!C24 -> jadwal pelajaran | I24: user | Q24: Template/LP | R24: Login | S24: Register | T24: Dashboard | U24: Laporan | V24: user | AD24: =B24 -> Nurhalizah
A25: 21 | B25: ='Database Konstelation'!B25 -> Nurul Aini Nasution | C25: ruang osis | D25: buk maya | E25: pemilihan osis | I25: user | Q25: Template/LP | R25: Login | S25: Register | T25: Dashboard | U25: Laporan | V25: user | AD25: =B25 -> Nurul Aini Nasution
A26: 22 | B26: ='Database Konstelation'!B26 -> Raffa Ramadhan | E26: ='Database Konstelation'!C26 -> aplikasi pengumpulan tugas siswa | I26: user | Q26: Template/LP | R26: Login | S26: Register | T26: Dashboard | U26: Laporan | V26: user | AD26: =B26 -> Raffa Ramadhan
A27: 23 | B27: ='Database Konstelation'!B27 -> Reisha Armaini | C27: kantor guru | D27: mem mimi | E27: ='Database Konstelation'!C27 -> LMS | I27: user | Q27: Template/LP | R27: Login | S27: Register | T27: Dashboard | U27: Laporan | V27: user | AD27: =B27 -> Reisha Armaini
A28: 24 | B28: ='Database Konstelation'!B28 -> Sarki Sepriana | C28: uks | D28: buk eli uks | E28: ='Database Konstelation'!C28 -> asuransi kesehatan untuk guru | I28: user | Q28: Template/LP | R28: Login | S28: Register | T28: Dashboard | U28: Laporan | V28: user | AD28: =B28 -> Sarki Sepriana
A29: 25 | B29: ='Database Konstelation'!B29 -> Sevenna Mesyera | C29: ruangan osis | D29: buk maya | E29: ='Database Konstelation'!C29 -> buku anggota Osis | Q29: Template/LP | R29: Login | S29: Register | T29: Dashboard | U29: Laporan | V29: user | AD29: =B29 -> Sevenna Mesyera
A30: 26 | B30: ='Database Konstelation'!B30 -> Shifa Rahmadani | C30: sarana | D30: buk nurul azizah | E30: ='Database Konstelation'!C30 -> Pengajuan Perlengkapan Alat LAB | Q30: Template/LP | R30: Login | S30: Register | T30: Dashboard | U30: Laporan | V30: user | AD30: =B30 -> Shifa Rahmadani
A31: 27 | B31: ='Database Konstelation'!B31 -> Tasya Aulia Putri | C31: ruang kelas | D31: ma'am minarti | E31: ='Database Konstelation'!C31 -> izin keluar kelas | Q31: Template/LP | R31: Login | S31: Register | T31: Dashboard | U31: Laporan | V31: user | AD31: =B31 -> Tasya Aulia Putri
A32: 28 | B32: ='Database Konstelation'!B32 -> Teuku Abdul Razaq | C32: sarana | D32: buk nurul azizah | E32: ='Database Konstelation'!C32 -> peminjaman alat sarana | Q32: Template/LP | R32: Login | S32: Register | T32: Dashboard | U32: Laporan | V32: user | AD32: =B32 -> Teuku Abdul Razaq
A33: 29 | B33: ='Database Konstelation'!B33 -> Wanda Afrilia | E33: ='Database Konstelation'!C33 -> pengaduan kerusakan fasilitas sklh | Q33: Template/LP | R33: Login | S33: Register | T33: Dashboard | U33: Laporan | V33: user | AD33: =B33 -> Wanda Afrilia
A34: 30 | B34: ='Database Konstelation'!B34 -> Widya Ulfa | E34: ='Database Konstelation'!C34 -> manejemen prestasi siswa | Q34: Template/LP | R34: Login | S34: Register | T34: Dashboard | U34: Laporan | V34: user | AD34: =B34 -> Widya Ulfa
A35: 31 | B35: ='Database Konstelation'!B35 -> Zahira Nursafa | C35: ruang kelas | D35: mam minarti | E35: ='Database Konstelation'!C35 -> uang kas | Q35: Template/LP | R35: Login | S35: Register | T35: Dashboard | U35: Laporan | V35: user | AD35: =B35 -> Zahira Nursafa
A36: 32 | B36: ='Database Konstelation'!B36 -> Zakwan Abdul Hady | C36: kantin | E36: ='Database Konstelation'!C36 -> aplikasi kantin sekolah | Q36: Template/LP | R36: Login | S36: Register | T36: Dashboard | U36: Laporan | V36: user | AD36: =B36 -> Zakwan Abdul Hady
A37: 33 | B37: ='Database Konstelation'!B37 -> Zsaskia Meiranda | C37: ruang osis | D37: buk maya | E37: ='Database Konstelation'!C37 -> pendaftaran ekskul | Q37: Template/LP | R37: Login | S37: Register | T37: Dashboard | U37: Laporan | V37: user | AD37: =B37 -> Zsaskia Meiranda
A38: 34 | B38: ='Database Konstelation'!B38 -> Zulaika Fatarani | C38: uks | E38: UKS | Q38: Template/LP | R38: Login | S38: Register | T38: Dashboard | U38: Laporan | V38: user | AD38: =B38 -> Zulaika Fatarani
B40: FITUR | C40: Kolom (atribut)1 | D40: Kolom (atribut)2 | E40: Kolom (atribut)3 | I40: Kolom (atribut)5 | J40: dst
B41: admin (S1) | C41: idadmin | D41: namaadmin | E41: username | I41: nohp
B42: Subjek2 | C42: id_ | D42: nama_ | E42: username | I42: nohp
B43: Objek | C43: id_ | D43: nama_
...

Sheet Kendali TB-DB
A1: BREAKDOWN TABEL PADA DATABASE
A3: Nama Pengembang | C3: : nurul aini nst
A4: Nama Aplikasi | C4: : pemilihan osis nurul
A5: Lokasi | C5: : SMKN 1 Karang Baru
A6: Mesin Databse | C6: : MySQL
A7: Bahasa Pemrograman | C7: : PHP Fundamental (CRUD)
A9: No | B9: Tabel (Entitas) | C9: Atribut (Field)
C10: 1 | D10: 2 | E10: 3 | F10: 4 | G10: 5 | H10: 6 | I10: 7 | J10: 8 | K10: 9 | L10: 10 | M10: 11 | N10: 12
A11: 1 | B11: user | C11: iduser | D11: namauser | E11: username | F11: passworsd | G11: role | H11: alamat | I11: nohp | J11: foto
B12: keterangan | C12: pk | G12: admin,petugas
A13: 2 | B13: idkategori | C13: idkategori | D13: namakategori
B14: keterangan | C14: pk
A15: 3 | B15: siswa | C15: idsiswa | D15: namasiswa | E15: nisn | F15: kelas | G15: statuspemilih
B16: keterangan | C16: pk | D16: fk | G16: sudah/belum
A17: 4 | B17: guru | C17: idguru | D17: namaguru | E17: nip | F17: statuspemilih
B18: keterangan | C18: pk | F18: sudah/belum
A19: 5 | B19: kandidat | C19: idkandidat | D19: idkategori | E19: nomorurut | F19: nama | G19: visi | H19: misi | I19: foto
B20: keterangan | C20: pk | D20: fk
A21: 6 | B21: pemilihan | C21: idpemilihan | D21: iduser | E21: idsiswa | F21: idguru | G21: idkandidat | H21: tanggalpemilihan
B22: keterangan | C22: pk | D22: fk | E22: fk
A23: 7 | B23: detailpemilihan | C23: iddetailpemilihan | D23: idpemilihan
B24: keterangan | C24: pk | D24: fk
A25: 8
A27: 9
A29: 10
A31: 11

Sheet Kendali APK
A1: BREAKDOWN FITUR PADA APLIKASI
A3: Nama Pengembang | C3: : nurul aini nst
A4: Nama Aplikasi | C4: : pemilihan osis
A5: Lokasi | C5: : SMKN 1 Karang Baru
A6: Mesin Databse | C6: : MySQL
A7: Bahasa Pemrograman | C7: : PHP Fundamental (CRUD)
A9: No | B9: FITUR | C9: TABEL UTAMA | D9: TABEL TERKAIT | E9: USECASE(ROLE) | I9: KETERANGAN
E10: ADMIN | F10: PETUGAS | G10: PEMILIH | H10: TAMU
A11: 1 | B11: homepage | D11: kandidat,kategori | E11: ya | F11: ya | G11: ya | I11: belum
A12: 2 | B12: login user | C12: user | E12: ya | F12: ya | I12: belum
A13: 3 | B13: login pemilih | C13: siswa/guru | D13: guru, siswa | G13: ya | I13: belum
A14: 4 | B14: dashboard user | C14: user | D14: semua tabel | E14: ya | F14: ya | I14: belum
A15: 5 | B15: dashoard pemilih | C15: siswa/guru | D15: semua tabel | G15: ya | I15: belum
A16: 6 | B16: kelola user | C16: user | E16: ya | F16: ya | I16: belum
A17: 7 | B17: Kelola Data Siswa | C17: siswa | D17: pemilihan | E17: ya | F17: ya | I17: belum
A18: 8 | B18: Kelola Data Guru | C18: guru | D18: pemilihan | E18: ya | F18: ya | I18: belum
A19: 9 | B19: kelola kategori | C19: admin | D19: kandidat | E19: ya | F19: ya | I19: belum
A20: 10 | B20: kelola kandidat | C20: peminjam | D20: kategori | E20: ya | F20: ya | I20: belum
A21: 11 | B21: statuspemilihan | C21: siswa guru | D21: pemilihan | E21: ya | I21: belum
A22: 12 | B22: pemilihan | C22: pemilihan | D22: guru, siswa, kandidat, kategori | F22: ya | G22: ya | I22: belum
A23: 13 | B23: detail pemilihan | C23: detailpemilihan | D23: pemilihan | F23: ya | I23: belum
A24: 14 | B24: laropan/hasilpemilihan | C24: hasilpemilihan | D24: kandidat, kategori | E24: ya | F24: ya | I24: belum

Sheet Sheet2
A1: Fitur | B1: Pendukung | C1: Urgensi/Tingkat Kepentingan | I1: Nama Tabel | J1: Nama Kolom | K1: Tipe Data
C2: Create | D2: Read (tampil) | E2: Update | F2: Delete | G2: Pencarian | H2: Cetak | I2: admin | J2: idadmin | K2: int
A3: Login | B3: username | J3: idjabatan | K3: int
B4: password | J4: namaadmin | K4: varchar(100)
A5: Dashboard | B5: admin | J5: username | K5: varchar(50)
B6: pelanggan | J6: password | K6: varchar(255)
B7: barang | J7: foto | K7: varchar(255)
B8: penjualan | I8: jabatan | J8: idjabatan | K8: int
A9: user | B9: namaadmin | J9: namajabatan | K9: varchar(100)
B10: username | I10: peminjam | J10: idpeminjam | K10: int
B11: password | J11: idasal | K11: int
B12: alamat | J12: namapeminjam | K12: varchar(100)
A13: peminjam | B13: namapelanggan | J13: username | K13: varchar(50)
B14: username | J14: password | K14: varchar(255)
B15: password | J15: foto | K15: varchar(255)
B16: alamat | I16: asal | J16: idasal | K16: int
A17: buku | B17: namabarang | J17: namaasal | K17: varchar(100)
B18: kategori | I18: peminjaman | J18: idpeminjaman | K18: int
B19: merk | J19: idadmin | K19: int
B20: suplier | J20: idpeminjam | K20: int
B21: stok | J21: foto | K21: varchar(100)
B22: harga | I22: detilpeminjaman | J22: iddetilpeminjaman | K22: int
A23: Barang->Kategori | B23: namakategori | J23: idpeminjaman | K23: int
A24: Barang->Suplier | B24: namakategori | J24: idalat | K24: int
B25: alamat | J25: tanggalpinjam | K25: date
A26: peminjaman | B26: nomor | J26: tanggalkembali | K26: date
B27: namapelanggan | I27: alat | J27: idalat | K27: int
B28: namaadmin | J28: idkategori | K28: int
B29: namabarang | J29: idmerk | K29: int
B30: jumlahbarang | J30: namaalat | K30: varchar(100)
B31: total | J31: kondisi | K31: varchar(50)
A32: Rekap/laporan | B32: rekap-harian | J32: idposisi | K32: int
A33: Cetak | B33: cetak | J33: tanggalpembelian | K33: date
A34: Total | J34: foto | K34: varchar(225)
I35: kategori | J35: idkategori | K35: int
J36: namakategori | K36: varchar(100)
I37: merk | J37: idmerk | K37: int
J38: namamerk | K38: varchar(100)
I39: posisi | J39: idposisi | K39: int
J40: namaposisi | K40: varchar(100)
